<mujoco model="free_floating_spacecraft_manipulator">
    <compiler angle="radian" />
    <option timestep="0.1" iterations="30">
        <flag gravity="disable" />
    </option>
    <size njmax="1000" nconmax="100" />
    <default class="main">
        <default class="panda">
            <joint limited="true" />
            <general ctrllimited="true" forcelimited="true" biastype="affine" biasprm="0 -1 0 0 0 0 0 0 0 0" />
            <default class="spaceRobot_viz">
                <geom type="mesh" contype="0" conaffinity="0" rgba="0.95 0.99 0.92 1" />
            </default>
            <default class="spaceRobot_col">
                <geom type="mesh" group="3" rgba="0.5 0.6 0.7 1" />
            </default>
            <default class="spaceRobot_finger">
                <joint armature="5" damping="100" />
                <geom conaffinity="0" condim="6" group="3" friction="1 0.5 0.0001" solref="0.01 1" solimp="0.8 0.9 0.001 0.5 2" margin="0.001" rgba="0.5 0.6 0.7 0.4" />
            </default>
        </default>
    </default>
    <asset>
        <texture type="skybox" name="space" file="space.png" />
        <texture type="2d" name="texplane" builtin="checker" rgb1="0.2 0.3 0.4" rgb2="0.1 0.15 0.2" width="512" height="512" />
        <material name="MatGnd" texture="texplane" texuniform="true" reflectance="0.5" />
        <mesh name="hand_col" file="meshes/collision/hand.stl" />
        <mesh name="finger_col" file="meshes/collision/finger.stl" scale="1.75 1 1.75" />
        <mesh name="hand_viz" file="meshes/visual/hand.stl" />
        <mesh name="finger_viz" file="meshes/collision/finger.stl" scale="1.75 1 1.75" />
    </asset>
    <worldbody>
        <site name="debrisSite" pos="-2 8 0" size="0.15" rgba="1 1 0.6 1" />
        <light pos="1 1 3" dir="-0.301511 -0.301511 -0.904534" diffuse="0.8 0.8 0.8" />
        <light pos="1 -1 3" dir="-0.301511 0.301511 -0.904534" diffuse="0.8 0.8 0.8" />
        <light pos="-1 0 3" dir="0.316228 0 -0.948683" diffuse="0.8 0.8 0.8" />
        <body name="spacecraft_base" pos="0 0 0">
            <inertial pos="0 0 0" mass="500" diaginertia="1400 1400 1040" />
            <joint name="BasefloatingJoint" type="free" />
            <geom size="1.05 1.05 1.05" type="box" rgba="1 1 0.6 1" />
            <site name="baseSite" pos="0 0 0" size="0.01" rgba="0.1 0.2 0.3 1" />
            <site name="rateX" pos="0 0 0" size="0.06 0.035 0.025" type="box" rgba="0.3 0.8 0.3 1" />
            <site name="rateY" pos="0 0 0" size="0.06 0.035 0.025" type="box" rgba="0.3 0.8 0.3 1" />
            <site name="rateZ" pos="0 0 0" size="0.06 0.035 0.025" type="box" rgba="0.3 0.8 0.3 1" />
            <body name="spacecraft_link1" pos="1.2268 1.2268 0" quat="0.653281 -0.653281 0.270598 -0.270598">
                <inertial pos="0 0 0" mass="20" diaginertia="0.1 0.1 0.1" />
                <joint name="sjoint1" pos="0 0 0" axis="0 0 1" limited="true" range="-3.14159 3.14159" damping="6413.59" />
                <geom size="0.04 0.25" type="cylinder" rgba="0 0 0.8 1" />
                <body name="spacecraft_link2" pos="-0.3182 0 -0.0682" quat="0.383235 0 -0.923651 0">
                    <inertial pos="0 0 0" quat="0.5 0.5 0.5 0.5" mass="30" diaginertia="25 25 0.25" />
                    <joint name="sjoint2" pos="0 0 -0.45" axis="0 1 0" limited="true" range="-3.14159 3.14159" damping="313.126" />
                    <geom size="0.04 0.45" type="cylinder" rgba="0 0.5 0.8 1" />
                    <body name="spacecraft_link3" pos="0 0 0.9">
                        <inertial pos="0 0 0" quat="0.5 0.5 0.5 0.5" mass="30" diaginertia="25 25 0.25" />
                        <joint name="sjoint3" pos="0 0 -0.45" axis="1 0 0" limited="true" range="-3.14159 3.14159" damping="267.211" />
                        <geom size="0.04 0.45" type="cylinder" rgba="0.5 0 0.8 1" />
                        <body name="spacecraft_link4" pos="0 0 0.85">
                            <inertial pos="0 0 0" quat="0.5 0.5 0.5 0.5" mass="20" diaginertia="25 25 0.25" />
                            <joint name="sjoint4" pos="0 0 -0.4" axis="0 1 0" limited="true" range="-3.14159 3.14159" damping="530.79" />
                            <geom size="0.04 0.4" type="cylinder" rgba="0.5 0.5 0.8 1" />
                            <body name="spacecraft_link5" pos="-0.4 0 0.4" quat="0.707388 0 -0.706825 0">
                                <inertial pos="0 0 0" quat="0.5 0.5 0.5 0.5" mass="20" diaginertia="25 25 0.25" />
                                <joint name="sjoint5" pos="0 0 -0.4" axis="0 1 0" limited="true" range="-3.14159 3.14159" damping="643.963" />
                                <geom size="0.04 0.4" type="cylinder" rgba="0.5 0 0.8 0.5" />
                                <body name="spacecraft_link6" pos="0 0 0.8">
                                    <inertial pos="0 0 0" quat="0.5 0.5 0.5 0.5" mass="20" diaginertia="25 25 0.25" />
                                    <joint name="sjoint6" pos="0 0 -0.4" axis="0 1 0" limited="true" range="-3.14159 3.14159" damping="1711.56" />
                                    <geom size="0.04 0.4" type="cylinder" />
                                    <body name="spacecraft_link7" pos="0 0 0.85">
                                        <inertial pos="0 0 0" quat="0.5 0.5 0.5 0.5" mass="20" diaginertia="25 25 0" />
                                        <joint name="sjoint7" pos="0 0 0" axis="0 0 1" limited="true" range="-3.14159 3.14159" damping="2509.88" />
                                        <geom size="0.04 0.45" type="cylinder" rgba="0.2 0.3 0.4 0.5" />
                                        <geom class="spaceRobot_viz" pos="0 0 0.45" quat="0.707388 0 0 -0.706825" mesh="hand_viz" />
                                        <geom class="spaceRobot_col" pos="0 0 0.45" quat="0.707388 0 0 -0.706825" mesh="hand_col" />
                                        <site name="end_effector" pos="0 0 0.56" quat="0.92388 0 0 -0.382683" size="0.01" />
                                        <camera name="Cam1" pos="0 0 0" mode="track" />
                                        <body name="leftfinger" childclass="spaceRobot_finger" pos="0 0 0.5154" quat="0.707388 0 0 -0.706825">
                                            <inertial pos="-1.57863e-05 0.0118731 0.0434103" quat="0.705868 0.0310348 -0.0314925 0.706962" mass="0.0927059" diaginertia="6.57134e-05 6.09611e-05 1.09932e-05" />
                                            <geom class="spaceRobot_viz" mesh="finger_viz" />
                                            <geom size="0.007 0.00912414" pos="0 0.0075 0.0875" quat="0.707107 0.116248 0.697486 0" type="capsule" />
                                            <geom size="0.007 0.00912414" pos="0 0.0075 0.0875" quat="0.707107 -0.116248 0.697486 0" type="capsule" />
                                            <geom size="0.0075 0.00912414" pos="0 0.0085 0.0775" quat="0.707107 0.116248 0.697486 0" type="capsule" />
                                            <geom size="0.0075 0.00912414" pos="0 0.0085 0.0775" quat="0.707107 -0.116248 0.697486 0" type="capsule" />
                                            <geom size="0.0082 0.00912414" pos="0 0.0095 0.0675" quat="0.707107 0.116248 0.697486 0" type="capsule" />
                                            <geom size="0.0082 0.00912414" pos="0 0.0095 0.0675" quat="0.707107 -0.116248 0.697486 0" type="capsule" />
                                            <geom size="0.009 0.00912414" pos="0 0.0105 0.0575" quat="0.707107 0.116248 0.697486 0" type="capsule" />
                                            <geom size="0.009 0.00912414" pos="0 0.0105 0.0575" quat="0.707107 -0.116248 0.697486 0" type="capsule" />
                                            <geom size="0.01 0.00912414" pos="0 0.012 0.0475" quat="0.707107 0.116248 0.697486 0" type="capsule" />
                                            <geom size="0.01 0.00912414" pos="0 0.012 0.0475" quat="0.707107 -0.116248 0.697486 0" type="capsule" />
                                            <geom size="0.011 0.00912414" pos="0 0.0135 0.035" quat="0.707107 0.116248 0.697486 0" type="capsule" />
                                            <geom size="0.011 0.00912414" pos="0 0.0135 0.035" quat="0.707107 -0.116248 0.697486 0" type="capsule" />
                                            <geom size="0.0185 0.012 0.0175" pos="0 0.014 0.015" quat="0.999888 0.0149994 0 0" type="box" />
                                        </body>
                                        <body name="rightfinger" childclass="spaceRobot_finger" pos="0 0 0.5154" quat="0.707388 0 0 -0.706825">
                                            <inertial pos="1.57863e-05 -0.0118731 0.0434103" quat="0.705868 -0.0310348 0.0314925 0.706962" mass="0.0927059" diaginertia="6.57134e-05 6.09611e-05 1.09932e-05" />
                                            <geom class="spaceRobot_viz" quat="0 0 0 1" mesh="finger_viz" />
                                            <geom size="0.007 0.00912414" pos="0 -0.0075 0.0875" quat="0.707107 -0.116248 0.697486 0" type="capsule" />
                                            <geom size="0.007 0.00912414" pos="0 -0.0075 0.0875" quat="0.707107 0.116248 0.697486 0" type="capsule" />
                                            <geom size="0.0075 0.00912414" pos="0 -0.0085 0.0775" quat="0.707107 -0.116248 0.697486 0" type="capsule" />
                                            <geom size="0.0075 0.00912414" pos="0 -0.0085 0.0775" quat="0.707107 0.116248 0.697486 0" type="capsule" />
                                            <geom size="0.0082 0.00912414" pos="0 -0.0095 0.0675" quat="0.707107 -0.116248 0.697486 0" type="capsule" />
                                            <geom size="0.0082 0.00912414" pos="0 -0.0095 0.0675" quat="0.707107 0.116248 0.697486 0" type="capsule" />
                                            <geom size="0.009 0.00912414" pos="0 -0.0105 0.0575" quat="0.707107 -0.116248 0.697486 0" type="capsule" />
                                            <geom size="0.009 0.00912414" pos="0 -0.0105 0.0575" quat="0.707107 0.116248 0.697486 0" type="capsule" />
                                            <geom size="0.01 0.00912414" pos="0 -0.012 0.0475" quat="0.707107 -0.116248 0.697486 0" type="capsule" />
                                            <geom size="0.01 0.00912414" pos="0 -0.012 0.0475" quat="0.707107 0.116248 0.697486 0" type="capsule" />
                                            <geom size="0.011 0.00912414" pos="0 -0.0135 0.035" quat="0.707107 -0.116248 0.697486 0" type="capsule" />
                                            <geom size="0.011 0.00912414" pos="0 -0.0135 0.035" quat="0.707107 0.116248 0.697486 0" type="capsule" />
                                            <geom size="0.0185 0.012 0.0175" pos="0 -0.014 0.015" quat="0.999888 -0.0149994 0 0" type="box" />
                                        </body>
                                    </body>
                                </body>
                            </body>
                        </body>
                    </body>
                </body>
            </body>
        </body>
    </worldbody>
    <actuator>
        <general name="motorX" site="baseSite" ctrllimited="true" ctrlrange="-0.08 0.08" />
        <general name="motorY" site="baseSite" ctrllimited="true" ctrlrange="-0.08 0.08" gear="0 1 0 0 0 0" />
        <general name="motorZ" site="baseSite" ctrllimited="true" ctrlrange="-0.08 0.08" gear="0 0 1 0 0 0" />
        <general site="rateX" ctrllimited="true" ctrlrange="-0.08 0.08" gear="0 0 0 1 0 0" biastype="affine" gainprm="0.1 0 0 0 0 0 0 0 0 0" biasprm="0 0 -0.1 0 0 0 0 0 0 0" />
        <general site="rateY" ctrllimited="true" ctrlrange="-0.08 0.08" gear="0 0 0 0 1 0" biastype="affine" gainprm="0.1 0 0 0 0 0 0 0 0 0" biasprm="0 0 -0.1 0 0 0 0 0 0 0" />
        <general site="rateZ" ctrllimited="true" ctrlrange="-0.08 0.08" gear="0 0 0 0 0 1" biastype="affine" gainprm="0.1 0 0 0 0 0 0 0 0 0" biasprm="0 0 -0.1 0 0 0 0 0 0 0" />
        <general name="motor1" joint="sjoint1" ctrllimited="true" ctrlrange="-3 3" />
        <general name="motor2" joint="sjoint2" ctrllimited="true" ctrlrange="-3 3" />
        <general name="motor3" joint="sjoint3" ctrllimited="true" ctrlrange="-0.1 0.1" />
        <general name="motor4" joint="sjoint4" ctrllimited="true" ctrlrange="-3 3" />
        <general name="motor5" joint="sjoint5" ctrllimited="true" ctrlrange="-3 3" />
        <general name="motor6" joint="sjoint6" ctrllimited="true" ctrlrange="-3 3" />
        <general name="motor7" joint="sjoint7" ctrllimited="true" ctrlrange="-3 3" />
    </actuator>
</mujoco>